[26/Jul/2023 13:51:47] DEBUG [asyncio:623] Using proactor: IocpProactor
[26/Jul/2023 13:52:25] DEBUG [asyncio:623] Using proactor: IocpProactor
[26/Jul/2023 13:53:03] WARNING [django.request:224] Not Found: /favicon.ico
[26/Jul/2023 13:53:03] WARNING [django.server:161] "GET /favicon.ico HTTP/1.1" 404 2116
[26/Jul/2023 13:57:01] DEBUG [asyncio:623] Using proactor: IocpProactor
[26/Jul/2023 13:57:01] DEBUG [asyncio:623] Using proactor: IocpProactor
[26/Jul/2023 13:57:52] DEBUG [asyncio:623] Using proactor: IocpProactor
[28/Jul/2023 12:15:02] WARNING [django.request:224] Not Found: /
[28/Jul/2023 12:15:02] WARNING [django.server:161] "GET / HTTP/1.1" 404 2172
[28/Jul/2023 12:21:25] ERROR [django.request:224] Internal Server Error: /seller/credit-decrease-transactions/
Traceback (most recent call last):
  File "C:\charge\charge\lib\site-packages\django\core\handlers\exception.py", line 47, in inner
    response = get_response(request)
  File "C:\charge\charge\lib\site-packages\django\core\handlers\base.py", line 181, in _get_response
    response = wrapped_callback(request, *callback_args, **callback_kwargs)
  File "C:\charge\charge\lib\site-packages\django\views\decorators\csrf.py", line 54, in wrapped_view
    return view_func(*args, **kwargs)
  File "C:\charge\charge\lib\site-packages\rest_framework\viewsets.py", line 125, in view
    return self.dispatch(request, *args, **kwargs)
  File "C:\charge\charge\lib\site-packages\rest_framework\views.py", line 509, in dispatch
    response = self.handle_exception(exc)
  File "C:\charge\charge\lib\site-packages\rest_framework\views.py", line 469, in handle_exception
    self.raise_uncaught_exception(exc)
  File "C:\charge\charge\lib\site-packages\rest_framework\views.py", line 480, in raise_uncaught_exception
    raise exc
  File "C:\charge\charge\lib\site-packages\rest_framework\views.py", line 506, in dispatch
    response = handler(request, *args, **kwargs)
  File "C:\charge\charge\lib\site-packages\rest_framework\mixins.py", line 19, in create
    self.perform_create(serializer)
  File "C:\charge\charge\lib\site-packages\rest_framework\mixins.py", line 24, in perform_create
    serializer.save()
  File "C:\charge\charge\lib\site-packages\rest_framework\serializers.py", line 212, in save
    self.instance = self.create(validated_data)
  File "C:\charge\charge\lib\site-packages\rest_framework\serializers.py", line 962, in create
    instance = ModelClass._default_manager.create(**validated_data)
  File "C:\charge\charge\lib\site-packages\django\db\models\manager.py", line 85, in manager_method
    return getattr(self.get_queryset(), name)(*args, **kwargs)
  File "C:\charge\charge\lib\site-packages\django\db\models\query.py", line 453, in create
    obj.save(force_insert=True, using=self.db)
  File "C:\Users\DigitalHouse\AppData\Local\Programs\Python\Python39\lib\contextlib.py", line 79, in inner
    return func(*args, **kwds)
  File "C:\ChargeSeller\seller\models.py", line 54, in save
    raise ValueError("Insufficient credit for credit decrease.")
ValueError: Insufficient credit for credit decrease.
[28/Jul/2023 12:21:25] ERROR [django.server:161] "POST /seller/credit-decrease-transactions/ HTTP/1.1" 500 129832
[28/Jul/2023 13:40:30] ERROR [django.request:224] Internal Server Error: /seller/charge-sale-transactions/
Traceback (most recent call last):
  File "C:\charge\charge\lib\site-packages\django\core\handlers\exception.py", line 47, in inner
    response = get_response(request)
  File "C:\charge\charge\lib\site-packages\django\core\handlers\base.py", line 181, in _get_response
    response = wrapped_callback(request, *callback_args, **callback_kwargs)
  File "C:\charge\charge\lib\site-packages\django\views\decorators\csrf.py", line 54, in wrapped_view
    return view_func(*args, **kwargs)
  File "C:\charge\charge\lib\site-packages\rest_framework\viewsets.py", line 125, in view
    return self.dispatch(request, *args, **kwargs)
  File "C:\charge\charge\lib\site-packages\rest_framework\views.py", line 509, in dispatch
    response = self.handle_exception(exc)
  File "C:\charge\charge\lib\site-packages\rest_framework\views.py", line 469, in handle_exception
    self.raise_uncaught_exception(exc)
  File "C:\charge\charge\lib\site-packages\rest_framework\views.py", line 480, in raise_uncaught_exception
    raise exc
  File "C:\charge\charge\lib\site-packages\rest_framework\views.py", line 506, in dispatch
    response = handler(request, *args, **kwargs)
  File "C:\charge\charge\lib\site-packages\rest_framework\mixins.py", line 19, in create
    self.perform_create(serializer)
  File "C:\charge\charge\lib\site-packages\rest_framework\mixins.py", line 24, in perform_create
    serializer.save()
  File "C:\charge\charge\lib\site-packages\rest_framework\serializers.py", line 212, in save
    self.instance = self.create(validated_data)
  File "C:\charge\charge\lib\site-packages\rest_framework\serializers.py", line 962, in create
    instance = ModelClass._default_manager.create(**validated_data)
  File "C:\charge\charge\lib\site-packages\django\db\models\manager.py", line 85, in manager_method
    return getattr(self.get_queryset(), name)(*args, **kwargs)
  File "C:\charge\charge\lib\site-packages\django\db\models\query.py", line 453, in create
    obj.save(force_insert=True, using=self.db)
  File "C:\Users\DigitalHouse\AppData\Local\Programs\Python\Python39\lib\contextlib.py", line 79, in inner
    return func(*args, **kwds)
  File "C:\ChargeSeller\seller\models.py", line 75, in save
    raise ValueError("Insufficient credit for charge sale.")
ValueError: Insufficient credit for charge sale.
[28/Jul/2023 14:09:49] ERROR [django.request:224] Internal Server Error: /seller/charge-sale-transactions/
Traceback (most recent call last):
  File "C:\charge\charge\lib\site-packages\django\core\handlers\exception.py", line 47, in inner
    response = get_response(request)
  File "C:\charge\charge\lib\site-packages\django\core\handlers\base.py", line 181, in _get_response
    response = wrapped_callback(request, *callback_args, **callback_kwargs)
  File "C:\charge\charge\lib\site-packages\django\views\decorators\csrf.py", line 54, in wrapped_view
    return view_func(*args, **kwargs)
  File "C:\charge\charge\lib\site-packages\rest_framework\viewsets.py", line 125, in view
    return self.dispatch(request, *args, **kwargs)
  File "C:\charge\charge\lib\site-packages\rest_framework\views.py", line 509, in dispatch
    response = self.handle_exception(exc)
  File "C:\charge\charge\lib\site-packages\rest_framework\views.py", line 469, in handle_exception
    self.raise_uncaught_exception(exc)
  File "C:\charge\charge\lib\site-packages\rest_framework\views.py", line 480, in raise_uncaught_exception
    raise exc
  File "C:\charge\charge\lib\site-packages\rest_framework\views.py", line 506, in dispatch
    response = handler(request, *args, **kwargs)
  File "C:\charge\charge\lib\site-packages\rest_framework\mixins.py", line 19, in create
    self.perform_create(serializer)
  File "C:\charge\charge\lib\site-packages\rest_framework\mixins.py", line 24, in perform_create
    serializer.save()
  File "C:\charge\charge\lib\site-packages\rest_framework\serializers.py", line 212, in save
    self.instance = self.create(validated_data)
  File "C:\charge\charge\lib\site-packages\rest_framework\serializers.py", line 962, in create
    instance = ModelClass._default_manager.create(**validated_data)
  File "C:\charge\charge\lib\site-packages\django\db\models\manager.py", line 85, in manager_method
    return getattr(self.get_queryset(), name)(*args, **kwargs)
  File "C:\charge\charge\lib\site-packages\django\db\models\query.py", line 453, in create
    obj.save(force_insert=True, using=self.db)
  File "C:\Users\DigitalHouse\AppData\Local\Programs\Python\Python39\lib\contextlib.py", line 79, in inner
    return func(*args, **kwds)
  File "C:\ChargeSeller\seller\models.py", line 75, in save
    raise ValueError("Insufficient credit for charge sale.")
ValueError: Insufficient credit for charge sale.
[28/Jul/2023 15:20:35] ERROR [django.request:224] Internal Server Error: /seller/charge-sale-transactions/
Traceback (most recent call last):
  File "C:\charge\charge\lib\site-packages\django\core\handlers\exception.py", line 47, in inner
    response = get_response(request)
  File "C:\charge\charge\lib\site-packages\django\core\handlers\base.py", line 181, in _get_response
    response = wrapped_callback(request, *callback_args, **callback_kwargs)
  File "C:\charge\charge\lib\site-packages\django\views\decorators\csrf.py", line 54, in wrapped_view
    return view_func(*args, **kwargs)
  File "C:\charge\charge\lib\site-packages\rest_framework\viewsets.py", line 125, in view
    return self.dispatch(request, *args, **kwargs)
  File "C:\charge\charge\lib\site-packages\rest_framework\views.py", line 509, in dispatch
    response = self.handle_exception(exc)
  File "C:\charge\charge\lib\site-packages\rest_framework\views.py", line 469, in handle_exception
    self.raise_uncaught_exception(exc)
  File "C:\charge\charge\lib\site-packages\rest_framework\views.py", line 480, in raise_uncaught_exception
    raise exc
  File "C:\charge\charge\lib\site-packages\rest_framework\views.py", line 506, in dispatch
    response = handler(request, *args, **kwargs)
  File "C:\charge\charge\lib\site-packages\rest_framework\mixins.py", line 19, in create
    self.perform_create(serializer)
  File "C:\charge\charge\lib\site-packages\rest_framework\mixins.py", line 24, in perform_create
    serializer.save()
  File "C:\charge\charge\lib\site-packages\rest_framework\serializers.py", line 212, in save
    self.instance = self.create(validated_data)
  File "C:\charge\charge\lib\site-packages\rest_framework\serializers.py", line 962, in create
    instance = ModelClass._default_manager.create(**validated_data)
  File "C:\charge\charge\lib\site-packages\django\db\models\manager.py", line 85, in manager_method
    return getattr(self.get_queryset(), name)(*args, **kwargs)
  File "C:\charge\charge\lib\site-packages\django\db\models\query.py", line 453, in create
    obj.save(force_insert=True, using=self.db)
  File "C:\Users\DigitalHouse\AppData\Local\Programs\Python\Python39\lib\contextlib.py", line 79, in inner
    return func(*args, **kwds)
  File "C:\ChargeSeller\seller\models.py", line 75, in save
    raise ValueError("Insufficient credit for charge sale.")
ValueError: Insufficient credit for charge sale.
[28/Jul/2023 15:26:54] ERROR [django.request:224] Internal Server Error: /seller/charge-sale-transactions/
Traceback (most recent call last):
  File "C:\charge\charge\lib\site-packages\django\core\handlers\exception.py", line 47, in inner
    response = get_response(request)
  File "C:\charge\charge\lib\site-packages\django\core\handlers\base.py", line 181, in _get_response
    response = wrapped_callback(request, *callback_args, **callback_kwargs)
  File "C:\charge\charge\lib\site-packages\django\views\decorators\csrf.py", line 54, in wrapped_view
    return view_func(*args, **kwargs)
  File "C:\charge\charge\lib\site-packages\rest_framework\viewsets.py", line 125, in view
    return self.dispatch(request, *args, **kwargs)
  File "C:\charge\charge\lib\site-packages\rest_framework\views.py", line 509, in dispatch
    response = self.handle_exception(exc)
  File "C:\charge\charge\lib\site-packages\rest_framework\views.py", line 469, in handle_exception
    self.raise_uncaught_exception(exc)
  File "C:\charge\charge\lib\site-packages\rest_framework\views.py", line 480, in raise_uncaught_exception
    raise exc
  File "C:\charge\charge\lib\site-packages\rest_framework\views.py", line 506, in dispatch
    response = handler(request, *args, **kwargs)
  File "C:\charge\charge\lib\site-packages\rest_framework\mixins.py", line 19, in create
    self.perform_create(serializer)
  File "C:\charge\charge\lib\site-packages\rest_framework\mixins.py", line 24, in perform_create
    serializer.save()
  File "C:\charge\charge\lib\site-packages\rest_framework\serializers.py", line 212, in save
    self.instance = self.create(validated_data)
  File "C:\charge\charge\lib\site-packages\rest_framework\serializers.py", line 962, in create
    instance = ModelClass._default_manager.create(**validated_data)
  File "C:\charge\charge\lib\site-packages\django\db\models\manager.py", line 85, in manager_method
    return getattr(self.get_queryset(), name)(*args, **kwargs)
  File "C:\charge\charge\lib\site-packages\django\db\models\query.py", line 453, in create
    obj.save(force_insert=True, using=self.db)
  File "C:\Users\DigitalHouse\AppData\Local\Programs\Python\Python39\lib\contextlib.py", line 79, in inner
    return func(*args, **kwds)
  File "C:\ChargeSeller\seller\models.py", line 75, in save
    raise ValueError("Insufficient credit for charge sale.")
ValueError: Insufficient credit for charge sale.
[28/Jul/2023 15:29:06] ERROR [django.request:224] Internal Server Error: /seller/charge-sale-transactions/
Traceback (most recent call last):
  File "C:\charge\charge\lib\site-packages\django\core\handlers\exception.py", line 47, in inner
    response = get_response(request)
  File "C:\charge\charge\lib\site-packages\django\core\handlers\base.py", line 181, in _get_response
    response = wrapped_callback(request, *callback_args, **callback_kwargs)
  File "C:\charge\charge\lib\site-packages\django\views\decorators\csrf.py", line 54, in wrapped_view
    return view_func(*args, **kwargs)
  File "C:\charge\charge\lib\site-packages\rest_framework\viewsets.py", line 125, in view
    return self.dispatch(request, *args, **kwargs)
  File "C:\charge\charge\lib\site-packages\rest_framework\views.py", line 509, in dispatch
    response = self.handle_exception(exc)
  File "C:\charge\charge\lib\site-packages\rest_framework\views.py", line 469, in handle_exception
    self.raise_uncaught_exception(exc)
  File "C:\charge\charge\lib\site-packages\rest_framework\views.py", line 480, in raise_uncaught_exception
    raise exc
  File "C:\charge\charge\lib\site-packages\rest_framework\views.py", line 506, in dispatch
    response = handler(request, *args, **kwargs)
  File "C:\charge\charge\lib\site-packages\rest_framework\mixins.py", line 19, in create
    self.perform_create(serializer)
  File "C:\charge\charge\lib\site-packages\rest_framework\mixins.py", line 24, in perform_create
    serializer.save()
  File "C:\charge\charge\lib\site-packages\rest_framework\serializers.py", line 212, in save
    self.instance = self.create(validated_data)
  File "C:\charge\charge\lib\site-packages\rest_framework\serializers.py", line 962, in create
    instance = ModelClass._default_manager.create(**validated_data)
  File "C:\charge\charge\lib\site-packages\django\db\models\manager.py", line 85, in manager_method
    return getattr(self.get_queryset(), name)(*args, **kwargs)
  File "C:\charge\charge\lib\site-packages\django\db\models\query.py", line 453, in create
    obj.save(force_insert=True, using=self.db)
  File "C:\Users\DigitalHouse\AppData\Local\Programs\Python\Python39\lib\contextlib.py", line 79, in inner
    return func(*args, **kwds)
  File "C:\ChargeSeller\seller\models.py", line 75, in save
    raise ValueError("Insufficient credit for charge sale.")
ValueError: Insufficient credit for charge sale.
[28/Jul/2023 15:29:36] ERROR [django.request:224] Internal Server Error: /seller/charge-sale-transactions/
Traceback (most recent call last):
  File "C:\charge\charge\lib\site-packages\django\core\handlers\exception.py", line 47, in inner
    response = get_response(request)
  File "C:\charge\charge\lib\site-packages\django\core\handlers\base.py", line 181, in _get_response
    response = wrapped_callback(request, *callback_args, **callback_kwargs)
  File "C:\charge\charge\lib\site-packages\django\views\decorators\csrf.py", line 54, in wrapped_view
    return view_func(*args, **kwargs)
  File "C:\charge\charge\lib\site-packages\rest_framework\viewsets.py", line 125, in view
    return self.dispatch(request, *args, **kwargs)
  File "C:\charge\charge\lib\site-packages\rest_framework\views.py", line 509, in dispatch
    response = self.handle_exception(exc)
  File "C:\charge\charge\lib\site-packages\rest_framework\views.py", line 469, in handle_exception
    self.raise_uncaught_exception(exc)
  File "C:\charge\charge\lib\site-packages\rest_framework\views.py", line 480, in raise_uncaught_exception
    raise exc
  File "C:\charge\charge\lib\site-packages\rest_framework\views.py", line 506, in dispatch
    response = handler(request, *args, **kwargs)
  File "C:\charge\charge\lib\site-packages\rest_framework\mixins.py", line 19, in create
    self.perform_create(serializer)
  File "C:\charge\charge\lib\site-packages\rest_framework\mixins.py", line 24, in perform_create
    serializer.save()
  File "C:\charge\charge\lib\site-packages\rest_framework\serializers.py", line 212, in save
    self.instance = self.create(validated_data)
  File "C:\charge\charge\lib\site-packages\rest_framework\serializers.py", line 962, in create
    instance = ModelClass._default_manager.create(**validated_data)
  File "C:\charge\charge\lib\site-packages\django\db\models\manager.py", line 85, in manager_method
    return getattr(self.get_queryset(), name)(*args, **kwargs)
  File "C:\charge\charge\lib\site-packages\django\db\models\query.py", line 453, in create
    obj.save(force_insert=True, using=self.db)
  File "C:\Users\DigitalHouse\AppData\Local\Programs\Python\Python39\lib\contextlib.py", line 79, in inner
    return func(*args, **kwds)
  File "C:\ChargeSeller\seller\models.py", line 75, in save
    raise ValueError("Insufficient credit for charge sale.")
ValueError: Insufficient credit for charge sale.
[29/Jul/2023 00:04:30] WARNING [django.request:224] Not Found: /seller/credit-incecrease-transactions/
[29/Jul/2023 00:04:30] WARNING [django.server:161] "POST /seller/credit-incecrease-transactions/ HTTP/1.1" 404 7277
[29/Jul/2023 00:11:01] WARNING [django.request:224] Not Found: /seller/charge-sale-transaction/
[29/Jul/2023 00:11:01] WARNING [django.server:161] "POST /seller/charge-sale-transaction/ HTTP/1.1" 404 7256
[29/Jul/2023 00:19:16] ERROR [django.request:224] Internal Server Error: /seller/credit-decrease-transactions/
Traceback (most recent call last):
  File "C:\charge\charge\lib\site-packages\django\core\handlers\exception.py", line 47, in inner
    response = get_response(request)
  File "C:\charge\charge\lib\site-packages\django\core\handlers\base.py", line 181, in _get_response
    response = wrapped_callback(request, *callback_args, **callback_kwargs)
  File "C:\charge\charge\lib\site-packages\django\views\decorators\csrf.py", line 54, in wrapped_view
    return view_func(*args, **kwargs)
  File "C:\charge\charge\lib\site-packages\rest_framework\viewsets.py", line 125, in view
    return self.dispatch(request, *args, **kwargs)
  File "C:\charge\charge\lib\site-packages\rest_framework\views.py", line 509, in dispatch
    response = self.handle_exception(exc)
  File "C:\charge\charge\lib\site-packages\rest_framework\views.py", line 469, in handle_exception
    self.raise_uncaught_exception(exc)
  File "C:\charge\charge\lib\site-packages\rest_framework\views.py", line 480, in raise_uncaught_exception
    raise exc
  File "C:\charge\charge\lib\site-packages\rest_framework\views.py", line 506, in dispatch
    response = handler(request, *args, **kwargs)
  File "C:\charge\charge\lib\site-packages\rest_framework\mixins.py", line 19, in create
    self.perform_create(serializer)
  File "C:\charge\charge\lib\site-packages\rest_framework\mixins.py", line 24, in perform_create
    serializer.save()
  File "C:\charge\charge\lib\site-packages\rest_framework\serializers.py", line 212, in save
    self.instance = self.create(validated_data)
  File "C:\charge\charge\lib\site-packages\rest_framework\serializers.py", line 962, in create
    instance = ModelClass._default_manager.create(**validated_data)
  File "C:\charge\charge\lib\site-packages\django\db\models\manager.py", line 85, in manager_method
    return getattr(self.get_queryset(), name)(*args, **kwargs)
  File "C:\charge\charge\lib\site-packages\django\db\models\query.py", line 453, in create
    obj.save(force_insert=True, using=self.db)
  File "C:\Users\DigitalHouse\AppData\Local\Programs\Python\Python39\lib\contextlib.py", line 79, in inner
    return func(*args, **kwds)
  File "C:\ChargeSeller\seller\models.py", line 54, in save
    raise ValueError("Insufficient credit for credit decrease.")
ValueError: Insufficient credit for credit decrease.
[29/Jul/2023 00:19:16] ERROR [django.server:161] "POST /seller/credit-decrease-transactions/ HTTP/1.1" 500 129900
[29/Jul/2023 00:28:20] ERROR [django.request:224] Internal Server Error: /seller/credit-decrease-transactions/
Traceback (most recent call last):
  File "C:\charge\charge\lib\site-packages\django\core\handlers\exception.py", line 47, in inner
    response = get_response(request)
  File "C:\charge\charge\lib\site-packages\django\core\handlers\base.py", line 181, in _get_response
    response = wrapped_callback(request, *callback_args, **callback_kwargs)
  File "C:\charge\charge\lib\site-packages\django\views\decorators\csrf.py", line 54, in wrapped_view
    return view_func(*args, **kwargs)
  File "C:\charge\charge\lib\site-packages\rest_framework\viewsets.py", line 125, in view
    return self.dispatch(request, *args, **kwargs)
  File "C:\charge\charge\lib\site-packages\rest_framework\views.py", line 509, in dispatch
    response = self.handle_exception(exc)
  File "C:\charge\charge\lib\site-packages\rest_framework\views.py", line 469, in handle_exception
    self.raise_uncaught_exception(exc)
  File "C:\charge\charge\lib\site-packages\rest_framework\views.py", line 480, in raise_uncaught_exception
    raise exc
  File "C:\charge\charge\lib\site-packages\rest_framework\views.py", line 506, in dispatch
    response = handler(request, *args, **kwargs)
  File "C:\ChargeSeller\seller\views.py", line 30, in create
    serializer.save()
  File "C:\charge\charge\lib\site-packages\rest_framework\serializers.py", line 212, in save
    self.instance = self.create(validated_data)
  File "C:\charge\charge\lib\site-packages\rest_framework\serializers.py", line 962, in create
    instance = ModelClass._default_manager.create(**validated_data)
  File "C:\charge\charge\lib\site-packages\django\db\models\manager.py", line 85, in manager_method
    return getattr(self.get_queryset(), name)(*args, **kwargs)
  File "C:\charge\charge\lib\site-packages\django\db\models\query.py", line 453, in create
    obj.save(force_insert=True, using=self.db)
  File "C:\Users\DigitalHouse\AppData\Local\Programs\Python\Python39\lib\contextlib.py", line 79, in inner
    return func(*args, **kwds)
  File "C:\ChargeSeller\seller\models.py", line 54, in save
    raise ValueError("Insufficient credit for credit decrease.")
ValueError: Insufficient credit for credit decrease.
[29/Jul/2023 00:28:20] ERROR [django.server:161] "POST /seller/credit-decrease-transactions/ HTTP/1.1" 500 125171
[29/Jul/2023 00:30:39] ERROR [django.request:224] Internal Server Error: /seller/credit-decrease-transactions/
Traceback (most recent call last):
  File "C:\charge\charge\lib\site-packages\django\core\handlers\exception.py", line 47, in inner
    response = get_response(request)
  File "C:\charge\charge\lib\site-packages\django\core\handlers\base.py", line 181, in _get_response
    response = wrapped_callback(request, *callback_args, **callback_kwargs)
  File "C:\charge\charge\lib\site-packages\django\views\decorators\csrf.py", line 54, in wrapped_view
    return view_func(*args, **kwargs)
  File "C:\charge\charge\lib\site-packages\rest_framework\viewsets.py", line 125, in view
    return self.dispatch(request, *args, **kwargs)
  File "C:\charge\charge\lib\site-packages\rest_framework\views.py", line 509, in dispatch
    response = self.handle_exception(exc)
  File "C:\charge\charge\lib\site-packages\rest_framework\views.py", line 469, in handle_exception
    self.raise_uncaught_exception(exc)
  File "C:\charge\charge\lib\site-packages\rest_framework\views.py", line 480, in raise_uncaught_exception
    raise exc
  File "C:\charge\charge\lib\site-packages\rest_framework\views.py", line 506, in dispatch
    response = handler(request, *args, **kwargs)
  File "C:\ChargeSeller\seller\views.py", line 30, in create
    serializer.save()
  File "C:\charge\charge\lib\site-packages\rest_framework\serializers.py", line 212, in save
    self.instance = self.create(validated_data)
  File "C:\charge\charge\lib\site-packages\rest_framework\serializers.py", line 962, in create
    instance = ModelClass._default_manager.create(**validated_data)
  File "C:\charge\charge\lib\site-packages\django\db\models\manager.py", line 85, in manager_method
    return getattr(self.get_queryset(), name)(*args, **kwargs)
  File "C:\charge\charge\lib\site-packages\django\db\models\query.py", line 453, in create
    obj.save(force_insert=True, using=self.db)
  File "C:\Users\DigitalHouse\AppData\Local\Programs\Python\Python39\lib\contextlib.py", line 79, in inner
    return func(*args, **kwds)
  File "C:\ChargeSeller\seller\models.py", line 54, in save
    raise ValueError("Insufficient credit for credit decrease.")
ValueError: Insufficient credit for credit decrease.
[29/Jul/2023 00:30:39] ERROR [django.server:161] "POST /seller/credit-decrease-transactions/ HTTP/1.1" 500 125171
[29/Jul/2023 00:42:18] WARNING [django.request:224] Bad Request: /seller/credit-decrease-transactions/
[29/Jul/2023 00:42:18] WARNING [django.server:161] "POST /seller/credit-decrease-transactions/ HTTP/1.1" 400 4
[29/Jul/2023 00:45:32] WARNING [django.request:224] Bad Request: /seller/credit-decrease-transactions/
[29/Jul/2023 00:45:32] WARNING [django.server:161] "POST /seller/credit-decrease-transactions/ HTTP/1.1" 400 101
[29/Jul/2023 00:47:59] WARNING [django.request:224] Bad Request: /seller/charge-sale-transactions/
[29/Jul/2023 00:47:59] WARNING [django.server:161] "POST /seller/charge-sale-transactions/ HTTP/1.1" 400 69
[29/Jul/2023 00:48:17] WARNING [django.request:224] Bad Request: /seller/charge-sale-transactions/
[29/Jul/2023 00:48:17] WARNING [django.server:161] "POST /seller/charge-sale-transactions/ HTTP/1.1" 400 68
[29/Jul/2023 00:48:25] WARNING [django.request:224] Bad Request: /seller/charge-sale-transactions/
[29/Jul/2023 00:48:25] WARNING [django.server:161] "POST /seller/charge-sale-transactions/ HTTP/1.1" 400 67
[29/Jul/2023 00:49:47] WARNING [django.request:224] Bad Request: /seller/charge-sale-transactions/
[29/Jul/2023 00:49:47] WARNING [django.server:161] "POST /seller/charge-sale-transactions/ HTTP/1.1" 400 67
[29/Jul/2023 00:49:52] WARNING [django.request:224] Bad Request: /seller/charge-sale-transactions/
[29/Jul/2023 00:49:52] WARNING [django.server:161] "POST /seller/charge-sale-transactions/ HTTP/1.1" 400 67
[29/Jul/2023 00:49:54] WARNING [django.request:224] Bad Request: /seller/charge-sale-transactions/
[29/Jul/2023 00:49:54] WARNING [django.server:161] "POST /seller/charge-sale-transactions/ HTTP/1.1" 400 67
[29/Jul/2023 00:49:56] WARNING [django.request:224] Bad Request: /seller/charge-sale-transactions/
[29/Jul/2023 00:49:56] WARNING [django.server:161] "POST /seller/charge-sale-transactions/ HTTP/1.1" 400 67
[29/Jul/2023 00:53:45] WARNING [django.request:224] Not Found: /
[29/Jul/2023 00:53:46] WARNING [django.server:161] "GET / HTTP/1.1" 404 2172
[29/Jul/2023 01:22:49] WARNING [django.request:224] Bad Request: /seller/credit-decrease-transactions/
[29/Jul/2023 01:22:49] WARNING [django.server:161] "POST /seller/credit-decrease-transactions/ HTTP/1.1" 400 69
[29/Jul/2023 12:22:07] WARNING [django.request:224] Not Found: /
[29/Jul/2023 12:22:07] WARNING [django.server:161] "GET / HTTP/1.1" 404 2172
[29/Jul/2023 12:26:44] WARNING [django.request:224] Bad Request: /seller/charge-sale-transactions/
[29/Jul/2023 12:26:44] WARNING [django.server:161] "POST /seller/charge-sale-transactions/ HTTP/1.1" 400 66
[29/Jul/2023 12:32:29] WARNING [django.request:224] Bad Request: /seller/charge-sale-transactions/
[29/Jul/2023 12:32:29] WARNING [django.server:161] "POST /seller/charge-sale-transactions/ HTTP/1.1" 400 66
[30/Jul/2023 21:41:56] WARNING [django.request:224] Not Found: /charge-sale-transactions/
[30/Jul/2023 21:41:56] WARNING [django.request:224] Not Found: /credit-increase-transactions/
[30/Jul/2023 21:43:12] WARNING [django.request:224] Not Found: /charge-sale-transactions/
[30/Jul/2023 21:43:12] WARNING [django.request:224] Not Found: /credit-increase-transactions
[30/Jul/2023 21:47:38] WARNING [django.request:224] Bad Request: /seller/charge-sale-transactions/
[30/Jul/2023 22:11:02] WARNING [django.request:224] Bad Request: /seller/charge-sale-transactions/
[30/Jul/2023 22:11:04] WARNING [django.request:224] Bad Request: /seller/charge-sale-transactions/
[30/Jul/2023 22:11:45] WARNING [django.request:224] Bad Request: /seller/charge-sale-transactions/
[30/Jul/2023 22:11:47] WARNING [django.request:224] Bad Request: /seller/charge-sale-transactions/
[30/Jul/2023 22:17:37] WARNING [django.request:224] Bad Request: /seller/charge-sale-transactions/
[30/Jul/2023 22:17:39] WARNING [django.request:224] Bad Request: /seller/charge-sale-transactions/
[30/Jul/2023 22:19:19] WARNING [django.request:224] Bad Request: /seller/charge-sale-transactions/
[30/Jul/2023 22:19:33] WARNING [django.request:224] Bad Request: /seller/charge-sale-transactions/
[30/Jul/2023 22:22:27] WARNING [django.request:224] Bad Request: /seller/charge-sale-transactions/
[30/Jul/2023 22:22:38] WARNING [django.request:224] Bad Request: /seller/charge-sale-transactions/
[30/Jul/2023 22:25:24] WARNING [django.request:224] Bad Request: /seller/charge-sale-transactions/
[30/Jul/2023 22:25:36] WARNING [django.request:224] Bad Request: /seller/charge-sale-transactions/
[31/Jul/2023 01:26:19] WARNING [django.request:224] Bad Request: /seller/charge-sale-transactions/
[31/Jul/2023 01:38:22] WARNING [django.request:224] Bad Request: /seller/charge-sale-transactions/
[31/Jul/2023 01:38:22] WARNING [django.request:224] Bad Request: /seller/charge-sale-transactions/
[31/Jul/2023 01:40:33] WARNING [django.request:224] Bad Request: /seller/charge-sale-transactions/
[31/Jul/2023 01:54:56] WARNING [django.request:224] Bad Request: /seller/charge-sale-transactions/
[31/Jul/2023 01:54:56] WARNING [django.request:224] Bad Request: /seller/charge-sale-transactions/
[31/Jul/2023 01:57:44] WARNING [django.request:224] Bad Request: /seller/charge-sale-transactions/
[31/Jul/2023 01:57:44] WARNING [django.request:224] Bad Request: /seller/charge-sale-transactions/
[31/Jul/2023 23:41:52] WARNING [django.request:224] Bad Request: /seller/charge-sale-transactions/
[31/Jul/2023 23:41:52] WARNING [django.request:224] Bad Request: /seller/charge-sale-transactions/
[31/Jul/2023 23:47:38] WARNING [django.request:224] Bad Request: /seller/charge-sale-transactions/
[31/Jul/2023 23:47:38] WARNING [django.request:224] Bad Request: /seller/charge-sale-transactions/
[31/Jul/2023 23:49:10] WARNING [django.request:224] Bad Request: /seller/charge-sale-transactions/
[31/Jul/2023 23:49:10] WARNING [django.request:224] Bad Request: /seller/charge-sale-transactions/
[31/Jul/2023 23:56:48] WARNING [django.request:224] Bad Request: /seller/charge-sale-transactions/
[31/Jul/2023 23:56:48] WARNING [django.request:224] Bad Request: /seller/charge-sale-transactions/
[01/Aug/2023 00:05:15] WARNING [django.request:224] Bad Request: /seller/charge-sale-transactions/
[01/Aug/2023 00:05:15] WARNING [django.request:224] Bad Request: /seller/charge-sale-transactions/
[01/Aug/2023 00:08:16] WARNING [django.request:224] Bad Request: /seller/charge-sale-transactions/
[02/Aug/2023 00:03:09] WARNING [django.request:224] Bad Request: /seller/charge-sale-transactions/
[02/Aug/2023 00:03:10] WARNING [django.request:224] Bad Request: /seller/charge-sale-transactions/
[02/Aug/2023 01:16:54] ERROR [django.request:224] Internal Server Error: /seller/credit-increase-transactions/
Traceback (most recent call last):
  File "c:\charge\charge\lib\site-packages\django\db\backends\utils.py", line 84, in _execute
    return self.cursor.execute(sql, params)
  File "c:\charge\charge\lib\site-packages\django\db\backends\sqlite3\base.py", line 423, in execute
    return Database.Cursor.execute(self, query, params)
sqlite3.OperationalError: database table is locked

The above exception was the direct cause of the following exception:

Traceback (most recent call last):
  File "c:\charge\charge\lib\site-packages\django\core\handlers\exception.py", line 47, in inner
    response = get_response(request)
  File "c:\charge\charge\lib\site-packages\django\core\handlers\base.py", line 181, in _get_response
    response = wrapped_callback(request, *callback_args, **callback_kwargs)
  File "c:\charge\charge\lib\site-packages\django\views\decorators\csrf.py", line 54, in wrapped_view
    return view_func(*args, **kwargs)
  File "c:\charge\charge\lib\site-packages\rest_framework\viewsets.py", line 125, in view
    return self.dispatch(request, *args, **kwargs)
  File "c:\charge\charge\lib\site-packages\rest_framework\views.py", line 509, in dispatch
    response = self.handle_exception(exc)
  File "c:\charge\charge\lib\site-packages\rest_framework\views.py", line 469, in handle_exception
    self.raise_uncaught_exception(exc)
  File "c:\charge\charge\lib\site-packages\rest_framework\views.py", line 480, in raise_uncaught_exception
    raise exc
  File "c:\charge\charge\lib\site-packages\rest_framework\views.py", line 506, in dispatch
    response = handler(request, *args, **kwargs)
  File "D:\ChargeSeller\seller\views.py", line 27, in create
    serializer.save()
  File "c:\charge\charge\lib\site-packages\rest_framework\serializers.py", line 212, in save
    self.instance = self.create(validated_data)
  File "c:\charge\charge\lib\site-packages\rest_framework\serializers.py", line 962, in create
    instance = ModelClass._default_manager.create(**validated_data)
  File "c:\charge\charge\lib\site-packages\django\db\models\manager.py", line 85, in manager_method
    return getattr(self.get_queryset(), name)(*args, **kwargs)
  File "c:\charge\charge\lib\site-packages\django\db\models\query.py", line 453, in create
    obj.save(force_insert=True, using=self.db)
  File "C:\Users\DigitalHouse\AppData\Local\Programs\Python\Python39\lib\contextlib.py", line 79, in inner
    return func(*args, **kwds)
  File "D:\ChargeSeller\seller\models.py", line 36, in save
    self.seller.save()
  File "D:\ChargeSeller\seller\models.py", line 21, in save
    super().save(*args, **kwargs)
  File "c:\charge\charge\lib\site-packages\django\db\models\base.py", line 739, in save
    self.save_base(using=using, force_insert=force_insert,
  File "c:\charge\charge\lib\site-packages\django\db\models\base.py", line 776, in save_base
    updated = self._save_table(
  File "c:\charge\charge\lib\site-packages\django\db\models\base.py", line 858, in _save_table
    updated = self._do_update(base_qs, using, pk_val, values, update_fields,
  File "c:\charge\charge\lib\site-packages\django\db\models\base.py", line 912, in _do_update
    return filtered._update(values) > 0
  File "c:\charge\charge\lib\site-packages\django\db\models\query.py", line 802, in _update
    return query.get_compiler(self.db).execute_sql(CURSOR)
  File "c:\charge\charge\lib\site-packages\django\db\models\sql\compiler.py", line 1559, in execute_sql
    cursor = super().execute_sql(result_type)
  File "c:\charge\charge\lib\site-packages\django\db\models\sql\compiler.py", line 1175, in execute_sql
    cursor.execute(sql, params)
  File "c:\charge\charge\lib\site-packages\django\db\backends\utils.py", line 66, in execute
    return self._execute_with_wrappers(sql, params, many=False, executor=self._execute)
  File "c:\charge\charge\lib\site-packages\django\db\backends\utils.py", line 75, in _execute_with_wrappers
    return executor(sql, params, many, context)
  File "c:\charge\charge\lib\site-packages\django\db\backends\utils.py", line 84, in _execute
    return self.cursor.execute(sql, params)
  File "c:\charge\charge\lib\site-packages\django\db\utils.py", line 90, in __exit__
    raise dj_exc_value.with_traceback(traceback) from exc_value
  File "c:\charge\charge\lib\site-packages\django\db\backends\utils.py", line 84, in _execute
    return self.cursor.execute(sql, params)
  File "c:\charge\charge\lib\site-packages\django\db\backends\sqlite3\base.py", line 423, in execute
    return Database.Cursor.execute(self, query, params)
django.db.utils.OperationalError: database table is locked
[02/Aug/2023 01:29:29] ERROR [django.request:224] Internal Server Error: /seller/credit-increase-transactions/
Traceback (most recent call last):
  File "c:\charge\charge\lib\site-packages\django\db\backends\utils.py", line 84, in _execute
    return self.cursor.execute(sql, params)
  File "c:\charge\charge\lib\site-packages\django\db\backends\sqlite3\base.py", line 423, in execute
    return Database.Cursor.execute(self, query, params)
sqlite3.OperationalError: database table is locked: seller_seller

The above exception was the direct cause of the following exception:

Traceback (most recent call last):
  File "c:\charge\charge\lib\site-packages\django\core\handlers\exception.py", line 47, in inner
    response = get_response(request)
  File "c:\charge\charge\lib\site-packages\django\core\handlers\base.py", line 181, in _get_response
    response = wrapped_callback(request, *callback_args, **callback_kwargs)
  File "c:\charge\charge\lib\site-packages\django\views\decorators\csrf.py", line 54, in wrapped_view
    return view_func(*args, **kwargs)
  File "c:\charge\charge\lib\site-packages\rest_framework\viewsets.py", line 125, in view
    return self.dispatch(request, *args, **kwargs)
  File "c:\charge\charge\lib\site-packages\rest_framework\views.py", line 509, in dispatch
    response = self.handle_exception(exc)
  File "c:\charge\charge\lib\site-packages\rest_framework\views.py", line 469, in handle_exception
    self.raise_uncaught_exception(exc)
  File "c:\charge\charge\lib\site-packages\rest_framework\views.py", line 480, in raise_uncaught_exception
    raise exc
  File "c:\charge\charge\lib\site-packages\rest_framework\views.py", line 506, in dispatch
    response = handler(request, *args, **kwargs)
  File "D:\ChargeSeller\seller\views.py", line 25, in create
    if serializer.is_valid():
  File "c:\charge\charge\lib\site-packages\rest_framework\serializers.py", line 227, in is_valid
    self._validated_data = self.run_validation(self.initial_data)
  File "c:\charge\charge\lib\site-packages\rest_framework\serializers.py", line 426, in run_validation
    value = self.to_internal_value(data)
  File "c:\charge\charge\lib\site-packages\rest_framework\serializers.py", line 483, in to_internal_value
    validated_value = field.run_validation(primitive_value)
  File "c:\charge\charge\lib\site-packages\rest_framework\relations.py", line 153, in run_validation
    return super().run_validation(data)
  File "c:\charge\charge\lib\site-packages\rest_framework\fields.py", line 547, in run_validation
    value = self.to_internal_value(data)
  File "c:\charge\charge\lib\site-packages\rest_framework\relations.py", line 264, in to_internal_value
    return queryset.get(pk=data)
  File "c:\charge\charge\lib\site-packages\django\db\models\query.py", line 431, in get
    num = len(clone)
  File "c:\charge\charge\lib\site-packages\django\db\models\query.py", line 262, in __len__
    self._fetch_all()
  File "c:\charge\charge\lib\site-packages\django\db\models\query.py", line 1324, in _fetch_all
    self._result_cache = list(self._iterable_class(self))
  File "c:\charge\charge\lib\site-packages\django\db\models\query.py", line 51, in __iter__
    results = compiler.execute_sql(chunked_fetch=self.chunked_fetch, chunk_size=self.chunk_size)
  File "c:\charge\charge\lib\site-packages\django\db\models\sql\compiler.py", line 1175, in execute_sql
    cursor.execute(sql, params)
  File "c:\charge\charge\lib\site-packages\django\db\backends\utils.py", line 66, in execute
    return self._execute_with_wrappers(sql, params, many=False, executor=self._execute)
  File "c:\charge\charge\lib\site-packages\django\db\backends\utils.py", line 75, in _execute_with_wrappers
    return executor(sql, params, many, context)
  File "c:\charge\charge\lib\site-packages\django\db\backends\utils.py", line 84, in _execute
    return self.cursor.execute(sql, params)
  File "c:\charge\charge\lib\site-packages\django\db\utils.py", line 90, in __exit__
    raise dj_exc_value.with_traceback(traceback) from exc_value
  File "c:\charge\charge\lib\site-packages\django\db\backends\utils.py", line 84, in _execute
    return self.cursor.execute(sql, params)
  File "c:\charge\charge\lib\site-packages\django\db\backends\sqlite3\base.py", line 423, in execute
    return Database.Cursor.execute(self, query, params)
django.db.utils.OperationalError: database table is locked: seller_seller
[02/Aug/2023 01:30:45] ERROR [django.request:224] Internal Server Error: /seller/credit-increase-transactions/
Traceback (most recent call last):
  File "c:\charge\charge\lib\site-packages\django\db\backends\utils.py", line 84, in _execute
    return self.cursor.execute(sql, params)
  File "c:\charge\charge\lib\site-packages\django\db\backends\sqlite3\base.py", line 423, in execute
    return Database.Cursor.execute(self, query, params)
sqlite3.OperationalError: database table is locked

The above exception was the direct cause of the following exception:

Traceback (most recent call last):
  File "c:\charge\charge\lib\site-packages\django\core\handlers\exception.py", line 47, in inner
    response = get_response(request)
  File "c:\charge\charge\lib\site-packages\django\core\handlers\base.py", line 181, in _get_response
    response = wrapped_callback(request, *callback_args, **callback_kwargs)
  File "c:\charge\charge\lib\site-packages\django\views\decorators\csrf.py", line 54, in wrapped_view
    return view_func(*args, **kwargs)
  File "c:\charge\charge\lib\site-packages\rest_framework\viewsets.py", line 125, in view
    return self.dispatch(request, *args, **kwargs)
  File "c:\charge\charge\lib\site-packages\rest_framework\views.py", line 509, in dispatch
    response = self.handle_exception(exc)
  File "c:\charge\charge\lib\site-packages\rest_framework\views.py", line 469, in handle_exception
    self.raise_uncaught_exception(exc)
  File "c:\charge\charge\lib\site-packages\rest_framework\views.py", line 480, in raise_uncaught_exception
    raise exc
  File "c:\charge\charge\lib\site-packages\rest_framework\views.py", line 506, in dispatch
    response = handler(request, *args, **kwargs)
  File "D:\ChargeSeller\seller\views.py", line 27, in create
    serializer.save()
  File "c:\charge\charge\lib\site-packages\rest_framework\serializers.py", line 212, in save
    self.instance = self.create(validated_data)
  File "c:\charge\charge\lib\site-packages\rest_framework\serializers.py", line 962, in create
    instance = ModelClass._default_manager.create(**validated_data)
  File "c:\charge\charge\lib\site-packages\django\db\models\manager.py", line 85, in manager_method
    return getattr(self.get_queryset(), name)(*args, **kwargs)
  File "c:\charge\charge\lib\site-packages\django\db\models\query.py", line 453, in create
    obj.save(force_insert=True, using=self.db)
  File "C:\Users\DigitalHouse\AppData\Local\Programs\Python\Python39\lib\contextlib.py", line 79, in inner
    return func(*args, **kwds)
  File "D:\ChargeSeller\seller\models.py", line 36, in save
    self.seller.save()
  File "D:\ChargeSeller\seller\models.py", line 21, in save
    super().save(*args, **kwargs)
  File "c:\charge\charge\lib\site-packages\django\db\models\base.py", line 739, in save
    self.save_base(using=using, force_insert=force_insert,
  File "c:\charge\charge\lib\site-packages\django\db\models\base.py", line 776, in save_base
    updated = self._save_table(
  File "c:\charge\charge\lib\site-packages\django\db\models\base.py", line 858, in _save_table
    updated = self._do_update(base_qs, using, pk_val, values, update_fields,
  File "c:\charge\charge\lib\site-packages\django\db\models\base.py", line 912, in _do_update
    return filtered._update(values) > 0
  File "c:\charge\charge\lib\site-packages\django\db\models\query.py", line 802, in _update
    return query.get_compiler(self.db).execute_sql(CURSOR)
  File "c:\charge\charge\lib\site-packages\django\db\models\sql\compiler.py", line 1559, in execute_sql
    cursor = super().execute_sql(result_type)
  File "c:\charge\charge\lib\site-packages\django\db\models\sql\compiler.py", line 1175, in execute_sql
    cursor.execute(sql, params)
  File "c:\charge\charge\lib\site-packages\django\db\backends\utils.py", line 66, in execute
    return self._execute_with_wrappers(sql, params, many=False, executor=self._execute)
  File "c:\charge\charge\lib\site-packages\django\db\backends\utils.py", line 75, in _execute_with_wrappers
    return executor(sql, params, many, context)
  File "c:\charge\charge\lib\site-packages\django\db\backends\utils.py", line 84, in _execute
    return self.cursor.execute(sql, params)
  File "c:\charge\charge\lib\site-packages\django\db\utils.py", line 90, in __exit__
    raise dj_exc_value.with_traceback(traceback) from exc_value
  File "c:\charge\charge\lib\site-packages\django\db\backends\utils.py", line 84, in _execute
    return self.cursor.execute(sql, params)
  File "c:\charge\charge\lib\site-packages\django\db\backends\sqlite3\base.py", line 423, in execute
    return Database.Cursor.execute(self, query, params)
django.db.utils.OperationalError: database table is locked
[02/Aug/2023 02:32:31] WARNING [django.request:224] Not Found: /charge-sale-transactions/
[02/Aug/2023 02:32:31] WARNING [django.server:161] "POST /charge-sale-transactions/ HTTP/1.1" 404 2266
[02/Aug/2023 02:32:31] WARNING [django.request:224] Not Found: /charge-sale-transactions/
[02/Aug/2023 02:32:31] WARNING [django.server:161] "POST /charge-sale-transactions/ HTTP/1.1" 404 2266
[02/Aug/2023 02:32:31] WARNING [django.request:224] Not Found: /charge-sale-transactions/
[02/Aug/2023 02:32:31] WARNING [django.server:161] "POST /charge-sale-transactions/ HTTP/1.1" 404 2266
[02/Aug/2023 02:32:31] WARNING [django.request:224] Not Found: /charge-sale-transactions/
[02/Aug/2023 02:32:31] WARNING [django.server:161] "POST /charge-sale-transactions/ HTTP/1.1" 404 2266
[02/Aug/2023 02:32:31] WARNING [django.request:224] Not Found: /charge-sale-transactions/
[02/Aug/2023 02:32:31] WARNING [django.server:161] "POST /charge-sale-transactions/ HTTP/1.1" 404 2266
[02/Aug/2023 02:32:31] WARNING [django.request:224] Not Found: /charge-sale-transactions/
[02/Aug/2023 02:32:31] WARNING [django.server:161] "POST /charge-sale-transactions/ HTTP/1.1" 404 2266
[02/Aug/2023 02:32:31] WARNING [django.request:224] Not Found: /charge-sale-transactions/
[02/Aug/2023 02:32:31] WARNING [django.server:161] "POST /charge-sale-transactions/ HTTP/1.1" 404 2266
[02/Aug/2023 02:32:31] WARNING [django.request:224] Not Found: /charge-sale-transactions/
[02/Aug/2023 02:32:31] WARNING [django.server:161] "POST /charge-sale-transactions/ HTTP/1.1" 404 2266
[02/Aug/2023 02:32:31] WARNING [django.request:224] Not Found: /charge-sale-transactions/
[02/Aug/2023 02:32:31] WARNING [django.server:161] "POST /charge-sale-transactions/ HTTP/1.1" 404 2266
[02/Aug/2023 02:32:31] WARNING [django.request:224] Not Found: /charge-sale-transactions/
[02/Aug/2023 02:32:31] WARNING [django.server:161] "POST /charge-sale-transactions/ HTTP/1.1" 404 2266
[02/Aug/2023 02:32:31] WARNING [django.request:224] Not Found: /charge-sale-transactions/
[02/Aug/2023 02:32:31] WARNING [django.server:161] "POST /charge-sale-transactions/ HTTP/1.1" 404 2266
[02/Aug/2023 02:32:31] WARNING [django.request:224] Not Found: /charge-sale-transactions/
[02/Aug/2023 02:32:31] WARNING [django.request:224] Not Found: /charge-sale-transactions/
[02/Aug/2023 02:32:31] WARNING [django.request:224] Not Found: /charge-sale-transactions/
[02/Aug/2023 02:32:31] WARNING [django.server:161] "POST /charge-sale-transactions/ HTTP/1.1" 404 2266
[02/Aug/2023 02:32:31] WARNING [django.request:224] Not Found: /charge-sale-transactions/
[02/Aug/2023 02:32:31] WARNING [django.server:161] "POST /charge-sale-transactions/ HTTP/1.1" 404 2266
[02/Aug/2023 02:32:31] WARNING [django.server:161] "POST /charge-sale-transactions/ HTTP/1.1" 404 2266
[02/Aug/2023 02:32:31] WARNING [django.request:224] Not Found: /charge-sale-transactions/
[02/Aug/2023 02:32:31] WARNING [django.server:161] "POST /charge-sale-transactions/ HTTP/1.1" 404 2266
[02/Aug/2023 02:32:32] WARNING [django.server:161] "POST /charge-sale-transactions/ HTTP/1.1" 404 2266
[02/Aug/2023 02:32:32] WARNING [django.request:224] Not Found: /charge-sale-transactions/
[02/Aug/2023 02:32:32] WARNING [django.request:224] Not Found: /charge-sale-transactions/
[02/Aug/2023 02:32:32] WARNING [django.request:224] Not Found: /charge-sale-transactions/
[02/Aug/2023 02:32:32] WARNING [django.request:224] Not Found: /charge-sale-transactions/
